Workbook

Sheet Elements
A1: HAYAMI'S ELEMENTAL FORM
A2: TIER 1 FORMS
A3: NO | B3: STATS | C3: EARTH | D3: LIGHTNING | E3: WIND | F3: FIRE | G3: WATER | H3: LEAF | I3: LIGHT
A4: 1 | B4: POWER | C4: 50 | D4: 65 | E4: 40 | F4: 65 | G4: 40 | H4: 38 | I4: 60
A5: 2 | B5: ENDURANCE | C5: 65 | D5: 50 | E5: 50 | F5: 50 | G5: 55 | H5: 67 | I5: 50
A6: 3 | B6: DEFENSE | C6: 70 | D6: 45 | E6: 45 | F6: 38 | G6: 60 | H6: 60 | I6: 45
A7: 4 | B7: AGILITY | C7: 35 | D7: 72 | E7: 70 | F7: 55 | G7: 65 | H7: 60 | I7: 75
A8: 5 | B8: INTELLIGENCE | C8: 55 | D8: 50 | E8: 50 | F8: 35 | G8: 55 | H8: 65 | I8: 70
A9: 6 | B9: PERCEPTION | C9: 50 | D9: 60 | E9: 55 | F9: 40 | G9: 60 | H9: 60 | I9: 70
A10: AVERAGE | C10: =AVERAGE(C4:C9) -> 54.166667 | D10: =AVERAGE(D4:D9) -> 57 | E10: =AVERAGE(E4:E9) -> 51.666667 | F10: =AVERAGE(F4:F9) -> 47.166667 | G10: =AVERAGE(G4:G9) -> 55.833333 | H10: =AVERAGE(H4:H9) -> 58.333333 | I10: =AVERAGE(I4:I9) -> 61.666667
A11: Max stat | C11: =MAX(C4:C9) -> 70 | D11: =MAX(D4:D9) -> 72 | E11: =MAX(E4:E9) -> 70 | F11: =MAX(F4:F9) -> 65 | G11: =MAX(G4:G9) -> 65 | H11: =MAX(H4:H9) -> 67 | I11: =MAX(I4:I9) -> 75
A12: Min stat | C12: =MIN(C4:C9) -> 35 | D12: =MIN(D4:D9) -> 45 | E12: =MIN(E4:E9) -> 40 | F12: =MIN(F4:F9) -> 35 | G12: =MIN(G4:G9) -> 40 | H12: =MIN(H4:H9) -> 38 | I12: =MIN(I4:I9) -> 45
A15: TIER 2 FORMS
A16: NO | B16: STATS | C16: EARTHQUAKE | D16: THUNDERSTORM | E16: CYCLONE | F16: BLAZE | G16: ICE | H16: THORN | I16: SOLAR
A17: 1 | B17: POWER | C17: 88 | D17: 95 | E17: 78 | F17: 91 | G17: 80 | H17: 82 | I17: 97
A18: 2 | B18: ENDURANCE | C18: 95 | D18: 76 | E18: 83 | F18: 80 | G18: 82 | H18: 97 | I18: 75
A19: 3 | B19: DEFENSE | C19: 97 | D19: 55 | E19: 76 | F19: 75 | G19: 88 | H19: 92 | I19: 55
A20: 4 | B20: AGILITY | C20: 50 | D20: 98 | E20: 95 | F20: 82 | G20: 67 | H20: 80 | I20: 99
A21: 5 | B21: INTELLIGENCE | C21: 80 | D21: 75 | E21: 76 | F21: 55 | G21: 90 | H21: 76 | I21: 98
A22: 6 | B22: PERCEPTION | C22: 76 | D22: 88 | E22: 80 | F22: 76 | G22: 95 | H22: 55 | I22: 88
A23: AVERAGE | C23: =AVERAGE(C17:C22) -> 81 | D23: =AVERAGE(D17:D22) -> 81.166667 | E23: =AVERAGE(E17:E22) -> 81.333333 | F23: =AVERAGE(F17:F22) -> 76.5 | G23: =AVERAGE(G17:G22) -> 83.666667 | H23: =AVERAGE(H17:H22) -> 80.333333 | I23: =AVERAGE(I17:I22) -> 85.333333
A24: Max stat | C24: =MAX(C17:C22) -> 97 | D24: =MAX(D17:D22) -> 98 | E24: =MAX(E17:E22) -> 95 | F24: =MAX(F17:F22) -> 91 | G24: =MAX(G17:G22) -> 95 | H24: =MAX(H17:H22) -> 97 | I24: =MAX(I17:I22) -> 99
A25: Min stat | C25: =MIN(C17:C22) -> 50 | D25: =MIN(D17:D22) -> 55 | E25: =MIN(E17:E22) -> 76 | F25: =MIN(F17:F22) -> 55 | G25: =MIN(G17:G22) -> 67 | H25: =MIN(H17:H22) -> 55 | I25: =MIN(I17:I22) -> 55

Sheet Characters
A3: NO | B3: NAME | C3: GROUP | D3: MBTI | E3: HEIGHT (cm) | F3: ACADEMIC | G3: SOCIAL | H3: STRATEGIC
A4: 1 | B4: PAULA | C4: ANALYST | D4: INTP | E4: 171 | F4: 5 | G4: 2 | H4: 5
A5: 2 | B5: HIROMI | C5: ANALYST | D5: INTJ | E5: 175 | F5: 5 | G5: 2 | H5: 5
A6: 3 | B6: MICA | C6: ANALYST | D6: ENTP | E6: 168 | F6: 4 | G6: 5 | H6: 4
A7: 4 | B7: GILLIAN | C7: ANALYST | D7: ENTJ | E7: 172 | F7: 4 | G7: 4 | H7: 5
A8: 5 | B8: HAYAMI | C8: EXPLORER | D8: ISTP | E8: 173 | F8: 5 | G8: 2 | H8: 5
A9: 6 | B9: SHIINA | C9: EXPLORER | D9: ISFP | E9: 165 | F9: 4 | G9: 3 | H9: 3
A10: 7 | B10: SHAYE | C10: EXPLORER | D10: ESTP | E10: 171 | F10: 4 | G10: 5 | H10: 4
A11: 8 | B11: THERESA | C11: EXPLORER | D11: ESFP | E11: 167 | F11: 2 | G11: 5 | H11: 2
A12: 9 | B12: CHIYO | C12: SENTINEL | D12: ISTJ | E12: 173 | F12: 5 | G12: 3 | H12: 5
A13: 10 | B13: MAYUMI | C13: SENTINEL | D13: ISFJ | E13: 168 | F13: 4 | G13: 3 | H13: 4
A14: 11 | B14: SHIZUKA | C14: SENTINEL | D14: ESTJ | E14: 169 | F14: 5 | G14: 4 | H14: 5
A15: 12 | B15: LILY | C15: SENTINEL | D15: ESFJ | E15: 167 | F15: 2 | G15: 5 | H15: 2
... A19: 16 | B19: HIMIKO | C19: DIPLOMAT | D19: ENFJ | E19: 169 | F19: 3 | G19: 5 | H19: 4
A22: NO | B22: NAME | C22: GROUP | D22: MBTI | E22: HEIGHT (cm) | F22: ACADEMIC | G22: SOCIAL | H22: STRATEGIC
A23: {=_xlfn._xlws.FILTER(A4:H19, Table1[GROUP]="Analyst")} -> 1 | B23: PAULA | C23: ANALYST | D23: INTP | E23: 171 | F23: 5 | G23: 2 | H23: 5
A24: 2 | B24: HIROMI | C24: ANALYST | D24: INTJ | E24: 175 | F24: 5 | G24: 2 | H24: 5
A25: 3 | B25: MICA | C25: ANALYST | D25: ENTP | E25: 168 | F25: 4 | G25: 5 | H25: 4
A26: 4 | B26: GILLIAN | C26: ANALYST | D26: ENTJ | E26: 172 | F26: 4 | G26: 4 | H26: 5
A28: NO | B28: NAME | C28: GROUP | D28: MBTI | E28: HEIGHT (cm) | F28: ACADEMIC | G28: SOCIAL | H28: STRATEGIC
A29: {=_xlfn._xlws.FILTER(Table1[], Table1[GROUP]="Explorer")} -> 5 | B29: HAYAMI | C29: EXPLORER | D29: ISTP | E29: 173 | F29: 5 | G29: 2 | H29: 5
A30: 6 | B30: SHIINA | C30: EXPLORER | D30: ISFP | E30: 165 | F30: 4 | G30: 3 | H30: 3
A31: 7 | B31: SHAYE | C31: EXPLORER | D31: ESTP | E31: 171 | F31: 4 | G31: 5 | H31: 4
A32: 8 | B32: THERESA | C32: EXPLORER | D32: ESFP | E32: 167 | F32: 2 | G32: 5 | H32: 2
A34: NO | B34: NAME | C34: GROUP | D34: MBTI | E34: HEIGHT (cm) | F34: ACADEMIC | G34: SOCIAL | H34: STRATEGIC
A35: {=_xlfn._xlws.FILTER(Table1[], Table1[GROUP]="sentinel")} -> 9 | B35: CHIYO | C35: SENTINEL | D35: ISTJ | E35: 173 | F35: 5 | G35: 3 | H35: 5
A36: 10 | B36: MAYUMI | C36: SENTINEL | D36: ISFJ | E36: 168 | F36: 4 | G36: 3 | H36: 4
A37: 11 | B37: SHIZUKA | C37: SENTINEL | D37: ESTJ | E37: 169 | F37: 5 | G37: 4 | H37: 5
A38: 12 | B38: LILY | C38: SENTINEL | D38: ESFJ | E38: 167 | F38: 2 | G38: 5 | H38: 2
A40: NO | B40: NAME | C40: GROUP | D40: MBTI | E40: HEIGHT (cm) | F40: ACADEMIC | G40: SOCIAL | H40: STRATEGIC
A41: {=_xlfn._xlws.FILTER(Table1[], Table1[GROUP]="diplomat")} -> 13 | B41: KATIE | C41: DIPLOMAT | D41: INFP | E41: 165 | F41: 3 | G41: 3 | H41: 3
A42: 14 | B42: SONIA | C42: DIPLOMAT | D42: INFJ | E42: 166 | F42: 3 | G42: 3 | H42: 3
A43: 15 | B43: EMILY | C43: DIPLOMAT | D43: ENFP | E43: 167 | F43: 2 | G43: 5 | H43: 2
A44: 16 | B44: HIMIKO | C44: DIPLOMAT | D44: ENFJ | E44: 169 | F44: 3 | G44: 5 | H44: 4
A47: {=_xlfn._xlws.SORT(Table1[#All], 7, -1)} -> NO | B47: NAME | C47: GROUP | D47: MBTI | E47: HEIGHT (cm) | F47: ACADEMIC | G47: SOCIAL | H47: STRATEGIC
A48: 3 | B48: MICA | C48: ANALYST | D48: ENTP | E48: 168 | F48: 4 | G48: 5 | H48: 4
A49: 7 | B49: SHAYE | C49: EXPLORER | D49: ESTP | E49: 171 | F49: 4 | G49: 5 | H49: 4
A50: 8 | B50: THERESA | C50: EXPLORER | D50: ESFP | E50: 167 | F50: 2 | G50: 5 | H50: 2
A51: 12 | B51: LILY | C51: SENTINEL | D51: ESFJ | E51: 167 | F51: 2 | G51: 5 | H51: 2
A52: 15 | B52: EMILY | C52: DIPLOMAT | D52: ENFP | E52: 167 | F52: 2 | G52: 5 | H52: 2
...

Sheet Stats
A1: NO | B1: NAME | C1: GROUP | D1: MBTI | E1: HEIGHT (cm) | F1: ACADEMIC | G1: SOCIAL | H1: STRATEGIC
A2: 1 | B2: PAULA | C2: ANALYST | D2: INTP | E2: 171 | F2: 5 | G2: 2 | H2: 5 | J2: Group | K2: Avg Academic | L2: Avg Social | M2: Avg Strategic
A3: 2 | B3: HIROMI | C3: ANALYST | D3: INTJ | E3: 175 | F3: 5 | G3: 2 | H3: 5 | J3: Analyst | K3: =AVERAGEIF(Table13[GROUP],"analyst",Table13[ACADEMIC]) -> 4.5 | L3: =AVERAGEIF(Table13[GROUP],"analyst",Table13[SOCIAL]) -> 3.25 | M3: =AVERAGEIF(Table13[GROUP],"analyst",Table13[STRATEGIC]) -> 4.75
A4: 3 | B4: MICA | C4: ANALYST | D4: ENTP | E4: 168 | F4: 4 | G4: 5 | H4: 4 | J4: Explorer | K4: =AVERAGEIF(Table13[GROUP],"explorer",Table13[ACADEMIC]) -> 3.75 | L4: =AVERAGEIF(Table13[GROUP],"explorer",Table13[SOCIAL]) -> 3.75 | M4: =AVERAGEIF(Table13[GROUP],"explorer",Table13[STRATEGIC]) -> 3.5
A5: 4 | B5: GILLIAN | C5: ANALYST | D5: ENTJ | E5: 172 | F5: 4 | G5: 4 | H5: 5 | J5: Sentinel | K5: =AVERAGEIF(Table13[GROUP],"sentinel",Table13[ACADEMIC]) -> 4 | L5: =AVERAGEIF(Table13[GROUP],"sentinel",Table13[SOCIAL]) -> 3.75 | M5: =AVERAGEIF(Table13[GROUP],"sentinel",Table13[STRATEGIC]) -> 4
A6: 5 | B6: HAYAMI | C6: EXPLORER | D6: ISTP | E6: 173 | F6: 5 | G6: 2 | H6: 5 | J6: Diplomat | K6: =AVERAGEIF(Table13[GROUP],"diplomat",Table13[ACADEMIC]) -> 2.75 | L6: =AVERAGEIF(Table13[GROUP],"diplomat",Table13[SOCIAL]) -> 4 | M6: =AVERAGEIF(Table13[GROUP],"diplomat",Table13[STRATEGIC]) -> 3
A7: 6 | B7: SHIINA | C7: EXPLORER | D7: ISFP | E7: 165 | F7: 4 | G7: 3 | H7: 3
A8: 7 | B8: SHAYE | C8: EXPLORER | D8: ESTP | E8: 171 | F8: 4 | G8: 5 | H8: 4
A9: 8 | B9: THERESA | C9: EXPLORER | D9: ESFP | E9: 167 | F9: 2 | G9: 5 | H9: 2
A10: 9 | B10: CHIYO | C10: SENTINEL | D10: ISTJ | E10: 173 | F10: 5 | G10: 3 | H10: 5
A11: 10 | B11: MAYUMI | C11: SENTINEL | D11: ISFJ | E11: 168 | F11: 4 | G11: 3 | H11: 4
A12: 11 | B12: SHIZUKA | C12: SENTINEL | D12: ESTJ | E12: 169 | F12: 5 | G12: 4 | H12: 5
A13: 12 | B13: LILY | C13: SENTINEL | D13: ESFJ | E13: 167 | F13: 2 | G13: 5 | H13: 2
A14: 13 | B14: KATIE | C14: DIPLOMAT | D14: INFP | E14: 165 | F14: 3 | G14: 3 | H14: 3
A15: 14 | B15: SONIA | C15: DIPLOMAT | D15: INFJ | E15: 166 | F15: 3 | G15: 3 | H15: 3
A16: 15 | B16: EMILY | C16: DIPLOMAT | D16: ENFP | E16: 167 | F16: 2 | G16: 5 | H16: 2
A17: 16 | B17: HIMIKO | C17: DIPLOMAT | D17: ENFJ | E17: 169 | F17: 3 | G17: 5 | H17: 4
B20: Name | C20: Academic | D20: Social | E20: Strategy
B21: Emily | C21: =VLOOKUP(B21,B1:H17,5,FALSE) -> 2 | D21: =VLOOKUP(B21,B1:H17,6,FALSE) -> 5 | E21: =VLOOKUP(B21,B1:H17,7,FALSE) -> 2

Sheet Stats_full
A1: NO | B1: NAME | C1: GROUP | D1: MBTI | E1: HEIGHT (cm) | F1: ACADEMIC | G1: SOCIAL | H1: STRATEGIC | I1: POWER | J1: DEFENSE
A2: 1 | B2: PAULA | C2: ANALYST | D2: INTP | E2: 171 | F2: 5 | G2: 2 | H2: 5 | I2: 4 | J2: 3
A3: 2 | B3: HIROMI | C3: ANALYST | D3: INTJ | E3: 175 | F3: 5 | G3: 2 | H3: 5 | I3: 5 | J3: 3
A4: 3 | B4: MICA | C4: ANALYST | D4: ENTP | E4: 168 | F4: 4 | G4: 5 | H4: 4 | I4: 4 | J4: 4
A5: 4 | B5: GILLIAN | C5: ANALYST | D5: ENTJ | E5: 172 | F5: 4 | G5: 4 | H5: 5 | I5: 5 | J5: 4
A6: 5 | B6: HAYAMI | C6: EXPLORER | D6: ISTP | E6: 173 | F6: 5 | G6: 2 | H6: 5 | I6: 5 | J6: 5
A7: 6 | B7: SHIINA | C7: EXPLORER | D7: ISFP | E7: 165 | F7: 4 | G7: 3 | H7: 3 | I7: 4 | J7: 3
A8: 7 | B8: SHAYE | C8: EXPLORER | D8: ESTP | E8: 171 | F8: 4 | G8: 5 | H8: 4 | I8: 4 | J8: 3
A9: 8 | B9: THERESA | C9: EXPLORER | D9: ESFP | E9: 167 | F9: 2 | G9: 5 | H9: 2 | I9: 3 | J9: 4
A10: 9 | B10: CHIYO | C10: SENTINEL | D10: ISTJ | E10: 173 | F10: 5 | G10: 2 | H10: 5 | I10: 4 | J10: 4
A11: 10 | B11: MAYUMI | C11: SENTINEL | D11: ISFJ | E11: 168 | F11: 4 | G11: 3 | H11: 4 | I11: 3 | J11: 5
A12: 11 | B12: SHIZUKA | C12: SENTINEL | D12: ESTJ | E12: 169 | F12: 5 | G12: 4 | H12: 5 | I12: 5 | J12: 4
A13: 12 | B13: LILY | C13: SENTINEL | D13: ESFJ | E13: 167 | F13: 2 | G13: 5 | H13: 2 | I13: 4 | J13: 2
... A17: 16 | B17: HIMIKO | C17: DIPLOMAT | D17: ENFJ | E17: 169 | F17: 3 | G17: 5 | H17: 4 | I17: 4 | J17: 3

Sheet Battle
B1: CHARACTER 1 | C1: VS | D1: CHARACTER 2
A2: Name | B2: HAYAMI | D2: SHAYE
A3: Academic | B3: =VLOOKUP(B2, Table134[[#All],[NAME]:[DEFENSE]], 5, FALSE) -> 5 | D3: =VLOOKUP(D2, Table134[[#All],[NAME]:[DEFENSE]], 5, FALSE) -> 4 | E3: =IF(B3>D3,B2,IF(D3>B3,D2,"TIE")) -> HAYAMI
A4: Social | B4: =VLOOKUP(B2, Table134[[#All],[NAME]:[DEFENSE]], 6, FALSE) -> 2 | D4: =VLOOKUP(D2, Table134[[#All],[NAME]:[DEFENSE]], 6, FALSE) -> 5 | E4: =IF(B4>D4,B2,IF(D4>B4,D2,"TIE")) -> SHAYE
A5: Strategic | B5: =VLOOKUP(B2, Table134[[#All],[NAME]:[DEFENSE]], 7, FALSE) -> 5 | D5: =VLOOKUP(D2, Table134[[#All],[NAME]:[DEFENSE]], 7, FALSE) -> 4 | E5: =IF(B5>D5,B2,IF(D5>B5,D2,"TIE")) -> HAYAMI
A6: Power | B6: =VLOOKUP(B2, Table134[[#All],[NAME]:[DEFENSE]], 8, FALSE) -> 5 | D6: =VLOOKUP(D2, Table134[[#All],[NAME]:[DEFENSE]], 8, FALSE) -> 4 | E6: =IF(B6>D6,B2,IF(D6>B6,D2,"TIE")) -> HAYAMI
A7: Defense | B7: =VLOOKUP(B2, Table134[[#All],[NAME]:[DEFENSE]], 9, FALSE) -> 5 | D7: =VLOOKUP(D2, Table134[[#All],[NAME]:[DEFENSE]], 9, FALSE) -> 3 | E7: =IF(B7>D7,B2,IF(D7>B7,D2,"TIE")) -> HAYAMI
A8: WINNER | B8: =IF(COUNTIF(E3:E7,B2)>COUNTIF(E3:E7,D2),B2, IF(COUNTIF(E3:E7,D2)>COUNTIF(E3:E7,B2),D2, "TIE")) -> HAYAMI

Sheet Fusion
A1: FUSION NAME | B1: ELEMENT 1 | C1: ELEMENT 2 | D1: STATUS | E1: EST. POWER RATING | F1: RATING BAR
A2: Ashfall | B2: Earthquake | C2: Blaze | D2: Undiscovered | E2: =AVERAGEIF(Fusion_stats!$A$2:$A$8, B2, Fusion_stats!$H$2:$H$8)/2 + AVERAGEIF(Fusion_stats!$A$2:$A$8, C2, Fusion_stats!$H$2:$H$8)/2 -> 78.75 | F2: =REPT("▪",ROUND((E2-MIN($E$2:$E$22))/(MAX($E$2:$E$22)-MIN($E$2:$E$22))*9+1, 0)) -> ▪
A3: Aurora | B3: Ice | C3: Solar | D3: Undiscovered | E3: =AVERAGEIF(Fusion_stats!$A$2:$A$8, B3, Fusion_stats!$H$2:$H$8)/2 + AVERAGEIF(Fusion_stats!$A$2:$A$8, C3, Fusion_stats!$H$2:$H$8)/2 -> 84.5 | F3: =REPT("▪",ROUND((E3-MIN($E$2:$E$22))/(MAX($E$2:$E$22)-MIN($E$2:$E$22))*9+1, 0)) -> ▪▪▪▪▪▪▪▪▪▪
A4: Briar | B4: Blaze | C4: Thorn | D4: Undiscovered | E4: =AVERAGEIF(Fusion_stats!$A$2:$A$8, B4, Fusion_stats!$H$2:$H$8)/2 + AVERAGEIF(Fusion_stats!$A$2:$A$8, C4, Fusion_stats!$H$2:$H$8)/2 -> 78.416667 | F4: =REPT("▪",ROUND((E4-MIN($E$2:$E$22))/(MAX($E$2:$E$22)-MIN($E$2:$E$22))*9+1, 0)) -> ▪
A5: Canopy | B5: Cyclone | C5: Thorn | D5: Undiscovered | E5: =AVERAGEIF(Fusion_stats!$A$2:$A$8, B5, Fusion_stats!$H$2:$H$8)/2 + AVERAGEIF(Fusion_stats!$A$2:$A$8, C5, Fusion_stats!$H$2:$H$8)/2 -> 80.833333 | F5: =REPT("▪",ROUND((E5-MIN($E$2:$E$22))/(MAX($E$2:$E$22)-MIN($E$2:$E$22))*9+1, 0)) -> ▪▪▪▪▪
A6: Cyclar | B6: Cyclone | C6: Solar | D6: Discovered | E6: =AVERAGEIF(Fusion_stats!$A$2:$A$8, B6, Fusion_stats!$H$2:$H$8)/2 + AVERAGEIF(Fusion_stats!$A$2:$A$8, C6, Fusion_stats!$H$2:$H$8)/2 -> 83.333333 | F6: =REPT("▪",ROUND((E6-MIN($E$2:$E$22))/(MAX($E$2:$E$22)-MIN($E$2:$E$22))*9+1, 0)) -> ▪▪▪▪▪▪▪▪
A7: Emberstorm | B7: Cyclone | C7: Blaze | D7: Undiscovered | E7: =AVERAGEIF(Fusion_stats!$A$2:$A$8, B7, Fusion_stats!$H$2:$H$8)/2 + AVERAGEIF(Fusion_stats!$A$2:$A$8, C7, Fusion_stats!$H$2:$H$8)/2 -> 78.916667 | F7: =REPT("▪",ROUND((E7-MIN($E$2:$E$22))/(MAX($E$2:$E$22)-MIN($E$2:$E$22))*9+1, 0)) -> ▪▪
A8: Flashgale | B8: Thunderstorm | C8: Cyclone | D8: Undiscovered | E8: =AVERAGEIF(Fusion_stats!$A$2:$A$8, B8, Fusion_stats!$H$2:$H$8)/2 + AVERAGEIF(Fusion_stats!$A$2:$A$8, C8, Fusion_stats!$H$2:$H$8)/2 -> 81.25 | F8: =REPT("▪",ROUND((E8-MIN($E$2:$E$22))/(MAX($E$2:$E$22)-MIN($E$2:$E$22))*9+1, 0)) -> ▪▪▪▪▪
A9: FrostFire | B9: Blaze | C9: Ice | D9: Discovered | E9: =AVERAGEIF(Fusion_stats!$A$2:$A$8, B9, Fusion_stats!$H$2:$H$8)/2 + AVERAGEIF(Fusion_stats!$A$2:$A$8, C9, Fusion_stats!$H$2:$H$8)/2 -> 80.083333 | F9: =REPT("▪",ROUND((E9-MIN($E$2:$E$22))/(MAX($E$2:$E$22)-MIN($E$2:$E$22))*9+1, 0)) -> ▪▪▪
A10: Glacier | B10: Earthquake | C10: Ice | D10: Discovered | E10: =AVERAGEIF(Fusion_stats!$A$2:$A$8, B10, Fusion_stats!$H$2:$H$8)/2 + AVERAGEIF(Fusion_stats!$A$2:$A$8, C10, Fusion_stats!$H$2:$H$8)/2 -> 82.333333 | F10: =REPT("▪",ROUND((E10-MIN($E$2:$E$22))/(MAX($E$2:$E$22)-MIN($E$2:$E$22))*9+1, 0)) -> ▪▪▪▪▪▪▪
A11: Hailstorm | B11: Thunderstorm | C11: Ice | D11: Undiscovered | E11: =AVERAGEIF(Fusion_stats!$A$2:$A$8, B11, Fusion_stats!$H$2:$H$8)/2 + AVERAGEIF(Fusion_stats!$A$2:$A$8, C11, Fusion_stats!$H$2:$H$8)/2 -> 82.416667 | F11: =REPT("▪",ROUND((E11-MIN($E$2:$E$22))/(MAX($E$2:$E$22)-MIN($E$2:$E$22))*9+1, 0)) -> ▪▪▪▪▪▪▪
A12: Ironleaf | B12: Earthquake | C12: Solar | D12: Undiscovered | E12: =AVERAGEIF(Fusion_stats!$A$2:$A$8, B12, Fusion_stats!$H$2:$H$8)/2 + AVERAGEIF(Fusion_stats!$A$2:$A$8, C12, Fusion_stats!$H$2:$H$8)/2 -> 83.166667 | F12: =REPT("▪",ROUND((E12-MIN($E$2:$E$22))/(MAX($E$2:$E$22)-MIN($E$2:$E$22))*9+1, 0)) -> ▪▪▪▪▪▪▪▪
A13: Mistveil | B13: Cyclone | C13: Ice | D13: Undiscovered | E13: =AVERAGEIF(Fusion_stats!$A$2:$A$8, B13, Fusion_stats!$H$2:$H$8)/2 + AVERAGEIF(Fusion_stats!$A$2:$A$8, C13, Fusion_stats!$H$2:$H$8)/2 -> 82.5 | F13: =REPT("▪",ROUND((E13-MIN($E$2:$E$22))/(MAX($E$2:$E$22)-MIN($E$2:$E$22))*9+1, 0)) -> ▪▪▪▪▪▪▪
... A22: Verdant | B22: Earthquake | C22: Thorn | D22: Undiscovered | E22: =AVERAGEIF(Fusion_stats!$A$2:$A$8, B22, Fusion_stats!$H$2:$H$8)/2 + AVERAGEIF(Fusion_stats!$A$2:$A$8, C22, Fusion_stats!$H$2:$H$8)/2 -> 80.666667 | F22: =REPT("▪",ROUND((E22-MIN($E$2:$E$22))/(MAX($E$2:$E$22)-MIN($E$2:$E$22))*9+1, 0)) -> ▪▪▪▪

Sheet Fusion_stats
A1: STATS | B1: POW | C1: END | D1: DEF | E1: AGI | F1: INT | G1: PER | H1: AVERAGE | I1: Max stat | J1: Min stat
A2: BLAZE | B2: 91 | C2: 80 | D2: 75 | E2: 82 | F2: 55 | G2: 76 | H2: =AVERAGE(B2:G2) -> 76.5 | I2: =MAX(B2:G2) -> 91 | J2: =MIN(B2:G2) -> 55
A3: CYCLONE | B3: 78 | C3: 83 | D3: 76 | E3: 95 | F3: 76 | G3: 80 | H3: =AVERAGE(B3:G3) -> 81.333333 | I3: =MAX(B3:G3) -> 95 | J3: =MIN(B3:G3) -> 76
A4: EARTHQUAKE | B4: 88 | C4: 95 | D4: 97 | E4: 50 | F4: 80 | G4: 76 | H4: =AVERAGE(B4:G4) -> 81 | I4: =MAX(B4:G4) -> 97 | J4: =MIN(B4:G4) -> 50
A5: ICE | B5: 80 | C5: 82 | D5: 88 | E5: 67 | F5: 90 | G5: 95 | H5: =AVERAGE(B5:G5) -> 83.666667 | I5: =MAX(B5:G5) -> 95 | J5: =MIN(B5:G5) -> 67
A6: SOLAR | B6: 97 | C6: 75 | D6: 55 | E6: 99 | F6: 98 | G6: 88 | H6: =AVERAGE(B6:G6) -> 85.333333 | I6: =MAX(B6:G6) -> 99 | J6: =MIN(B6:G6) -> 55
A7: THORN | B7: 82 | C7: 97 | D7: 92 | E7: 80 | F7: 76 | G7: 55 | H7: =AVERAGE(B7:G7) -> 80.333333 | I7: =MAX(B7:G7) -> 97 | J7: =MIN(B7:G7) -> 55
A8: THUNDERSTORM | B8: 95 | C8: 76 | D8: 55 | E8: 98 | F8: 75 | G8: 88 | H8: =AVERAGE(B8:G8) -> 81.166667 | I8: =MAX(B8:G8) -> 98 | J8: =MIN(B8:G8) -> 55

Sheet Relationship
B1: PAULA | C1: HIROMI | D1: MICA | E1: GILLIAN | F1: HAYAMI | G1: SHIINA | H1: SHAYE | I1: THERESA | J1: CHIYO | K1: MAYUMI | L1: SHIZUKA | M1: LILY | N1: KATIE | O1: SONIA | P1: EMILY | Q1: HIMIKO
A2: PAULA | C2: 9 | D2: 9 | E2: 8 | F2: 10 | G2: 6 | H2: 6 | I2: 5 | J2: 7 | K2: 8 | L2: 5 | M2: 5 | N2: 6 | O2: 5 | P2: 6 | Q2: 6 | S2: SCALE 1 - 10 | T2: Meaning
A3: HIROMI | B3: 9 | D3: 8 | E3: 8 | F3: 9 | G3: 7 | H3: 5 | I3: 5 | J3: 8 | K3: 8 | L3: 9 | M3: 5 | N3: 5 | O3: 6 | P3: 6 | Q3: 6 | S3: 1 | T3: No interaction
A4: MICA | B4: 9 | C4: 8 | E4: 8 | F4: 7 | G4: 6 | H4: 10 | I4: 9 | J4: 5 | K4: 7 | L4: 7 | M4: 6 | N4: 5 | O4: 5 | P4: 9 | Q4: 6 | S4: 2 | T4: Recognition
A5: GILLIAN | B5: 8 | C5: 8 | D5: 8 | F5: 7 | G5: 6 | H5: 6 | I5: 5 | J5: 8 | K5: 8 | L5: 10 | M5: 5 | N5: 5 | O5: 5 | P5: 5 | Q5: 6 | S5: 3 | T5: Basic interaction
A6: HAYAMI | B6: 10 | C6: 9 | D6: 7 | E6: 7 | G6: 9 | H6: 9 | I6: 8 | J6: 9 | K6: 8 | L6: 5 | M6: 6 | N6: 6 | O6: 5 | P6: 6 | Q6: 5 | S6: 4 | T6: Friendly
A7: SHIINA | B7: 6 | C7: 7 | D7: 6 | E7: 6 | F7: 9 | H7: 7 | I7: 8 | J7: 8 | K7: 10 | L7: 5 | M7: 7 | N7: 8 | O7: 8 | P7: 6 | Q7: 6 | S7: 5 | T7: Stable friendship
A8: SHAYE | B8: 6 | C8: 5 | D8: 10 | E8: 6 | F8: 9 | G8: 7 | I8: 10 | J8: 5 | K8: 7 | L8: 5 | M8: 6 | N8: 7 | O8: 5 | P8: 9 | Q8: 6 | S8: 6 | T8: Strong trust
A9: THERESA | B9: 5 | C9: 5 | D9: 9 | E9: 5 | F9: 8 | G9: 8 | H9: 10 | J9: 6 | K9: 7 | L9: 5 | M9: 9 | N9: 7 | O9: 6 | P9: 9 | Q9: 8 | S9: 7 | T9: Deep loyalty
A10: CHIYO | B10: 7 | C10: 8 | D10: 5 | E10: 8 | F10: 9 | G10: 8 | H10: 5 | I10: 6 | K10: 9 | L10: 10 | M10: 8 | N10: 7 | O10: 6 | P10: 6 | Q10: 8 | S10: 8 | T10: Extremily strong bond
A11: MAYUMI | B11: 8 | C11: 8 | D11: 7 | E11: 8 | F11: 8 | G11: 10 | H11: 7 | I11: 7 | J11: 9 | L11: 8 | M11: 10 | N11: 10 | O11: 9 | P11: 6 | Q11: 7 | S11: 9 | T11: Life connection
A12: SHIZUKA | B12: 5 | C12: 9 | D12: 7 | E12: 10 | F12: 5 | G12: 5 | H12: 5 | I12: 5 | J12: 10 | K12: 8 | M12: 7 | N12: 5 | O12: 5 | P12: 6 | Q12: 7 | S12: 10 | T12: Unbreakable
A13: LILY | B13: 5 | C13: 5 | D13: 6 | E13: 5 | F13: 6 | G13: 7 | H13: 6 | I13: 9 | J13: 8 | K13: 10 | L13: 7 | N13: 9 | O13: 9 | P13: 8 | Q13: 9
A14: KATIE | B14: 6 | C14: 5 | D14: 5 | E14: 5 | F14: 6 | G14: 8 | H14: 7 | I14: 7 | J14: 7 | K14: 10 | L14: 5 | M14: 9 | O14: 10 | P14: 9 | Q14: 8
A15: SONIA | B15: 5 | C15: 6 | D15: 5 | E15: 5 | F15: 5 | G15: 8 | H15: 5 | I15: 6 | J15: 6 | K15: 9 | L15: 5 | M15: 9 | N15: 10 | P15: 8 | Q15: 9
A16: EMILY | B16: 6 | C16: 6 | D16: 9 | E16: 5 | F16: 6 | G16: 6 | H16: 9 | I16: 9 | J16: 6 | K16: 6 | L16: 6 | M16: 8 | N16: 9 | O16: 8 | Q16: 8
A17: HIMIKO | B17: 6 | C17: 6 | D17: 6 | E17: 6 | F17: 5 | G17: 6 | H17: 6 | I17: 8 | J17: 8 | K17: 7 | L17: 7 | M17: 9 | N17: 8 | O17: 9 | P17: 8
A19: CHARACTERS | B19: Avg Score | D19: Most Positive | F19: Most Volatile
A20: PAULA | B20: =AVERAGE(B2:Q2) -> 6.7333333 | D20: =INDEX(B1:Q1, MATCH(MAX(B2:Q2), B2:Q2, 0)) -> HAYAMI | F20: =INDEX(B1:Q1, MATCH(MIN(B2:Q2), B2:Q2, 0)) -> THERESA
A21: HIROMI | B21: =AVERAGE(B3:Q3) -> 6.9333333 | D21: =INDEX(B1:Q1, MATCH(MAX(B3:Q3), B3:Q3, 0)) -> PAULA | F21: =INDEX(B1:Q1, MATCH(MIN(B3:Q3), B3:Q3, 0)) -> SHAYE
A22: MICA | B22: =AVERAGE(B4:Q4) -> 7.1333333 | D22: =INDEX(B1:Q1, MATCH(MAX(B4:Q4), B4:Q4, 0)) -> SHAYE | F22: =INDEX(B1:Q1, MATCH(MIN(B4:Q4), B4:Q4, 0)) -> CHIYO
A23: GILLIAN | B23: =AVERAGE(B5:Q5) -> 6.6666667 | D23: =INDEX(B1:Q1, MATCH(MAX(B5:Q5), B5:Q5, 0)) -> SHIZUKA | F23: =INDEX(B1:Q1, MATCH(MIN(B5:Q5), B5:Q5, 0)) -> THERESA
A24: HAYAMI | B24: =AVERAGE(B6:Q6) -> 7.2666667 | D24: =INDEX(B1:Q1, MATCH(MAX(B6:Q6), B6:Q6, 0)) -> PAULA | F24: =INDEX(B1:Q1, MATCH(MIN(B6:Q6), B6:Q6, 0)) -> SHIZUKA
A25: SHIINA | B25: =AVERAGE(B7:Q7) -> 7.1333333 | D25: =INDEX(B1:Q1, MATCH(MAX(B7:Q7), B7:Q7, 0)) -> MAYUMI | F25: =INDEX(B1:Q1, MATCH(MIN(B7:Q7), B7:Q7, 0)) -> SHIZUKA
A26: SHAYE | B26: =AVERAGE(B8:Q8) -> 6.8666667 | D26: =INDEX(B1:Q1, MATCH(MAX(B8:Q8), B8:Q8, 0)) -> MICA | F26: =INDEX(B1:Q1, MATCH(MIN(B8:Q8), B8:Q8, 0)) -> HIROMI
A27: THERESA | B27: =AVERAGE(B9:Q9) -> 7.1333333 | D27: =INDEX(B1:Q1, MATCH(MAX(B9:Q9), B9:Q9, 0)) -> SHAYE | F27: =INDEX(B1:Q1, MATCH(MIN(B9:Q9), B9:Q9, 0)) -> PAULA
A28: CHIYO | B28: =AVERAGE(B10:Q10) -> 7.3333333 | D28: =INDEX(B1:Q1, MATCH(MAX(B10:Q10), B10:Q10, 0)) -> SHIZUKA | F28: =INDEX(B1:Q1, MATCH(MIN(B10:Q10), B10:Q10, 0)) -> MICA
A29: MAYUMI | B29: =AVERAGE(B11:Q11) -> 8.1333333 | D29: =INDEX(B1:Q1, MATCH(MAX(B11:Q11), B11:Q11, 0)) -> SHIINA | F29: =INDEX(B1:Q1, MATCH(MIN(B11:Q11), B11:Q11, 0)) -> EMILY
A30: SHIZUKA | B30: =AVERAGE(B12:Q12) -> 6.6 | D30: =INDEX(B1:Q1, MATCH(MAX(B12:Q12), B12:Q12, 0)) -> GILLIAN | F30: =INDEX(B1:Q1, MATCH(MIN(B12:Q12), B12:Q12, 0)) -> PAULA
A31: LILY | B31: =AVERAGE(B13:Q13) -> 7.2666667 | D31: =INDEX(B1:Q1, MATCH(MAX(B13:Q13), B13:Q13, 0)) -> MAYUMI | F31: =INDEX(B1:Q1, MATCH(MIN(B13:Q13), B13:Q13, 0)) -> PAULA
A32: KATIE | B32: =AVERAGE(B14:Q14) -> 7.1333333 | D32: =INDEX(B1:Q1, MATCH(MAX(B14:Q14), B14:Q14, 0)) -> MAYUMI | F32: =INDEX(B1:Q1, MATCH(MIN(B14:Q14), B14:Q14, 0)) -> HIROMI
A33: SONIA | B33: =AVERAGE(B15:Q15) -> 6.7333333 | D33: =INDEX(B1:Q1, MATCH(MAX(B15:Q15), B15:Q15, 0)) -> KATIE | F33: =INDEX(B1:Q1, MATCH(MIN(B15:Q15), B15:Q15, 0)) -> PAULA
A34: EMILY | B34: =AVERAGE(B16:Q16) -> 7.1333333 | D34: =INDEX(B1:Q1, MATCH(MAX(B16:Q16), B16:Q16, 0)) -> MICA | F34: =INDEX(B1:Q1, MATCH(MIN(B16:Q16), B16:Q16, 0)) -> GILLIAN
A35: HIMIKO | B35: =AVERAGE(B17:Q17) -> 7 | D35: =INDEX(B1:Q1, MATCH(MAX(B17:Q17), B17:Q17, 0)) -> LILY | F35: =INDEX(B1:Q1, MATCH(MIN(B17:Q17), B17:Q17, 0)) -> HAYAMI

Sheet Chart
A1: Name | B1: Group | C1: Avg Stat | D1: Rank | E1: Tier | G1: Tier | H1: Count
A2: PAULA | B2: Analyst | C2: =AVERAGE(Table134[[#This Row],[ACADEMIC]],Table134[[#This Row],[SOCIAL]],Table134[[#This Row],[STRATEGIC]],Table134[[#This Row],[POWER]],Table134[[#This Row],[DEFENSE]]) -> 3.8 | D2: =RANK(C2,C2:C17,0) -> 8 | E2: =IF(C2>=PERCENTILE($C$2:$C$17, 0.75), "S", IF(C2>=PERCENTILE($C$2:$C$17, 0.5), "A", IF(C2>=PERCENTILE($C$2:$C$17, 0.25), "B", "C"))) -> A | G2: S | H2: =COUNTIF($E$2:$E$17, "S") -> 4
A3: HIROMI | B3: Analyst | C3: =AVERAGE(Table134[[#This Row],[ACADEMIC]],Table134[[#This Row],[SOCIAL]],Table134[[#This Row],[STRATEGIC]],Table134[[#This Row],[POWER]],Table134[[#This Row],[DEFENSE]]) -> 4 | D3: =RANK(C3,C2:C17,0) -> 5 | E3: =IF(C3>=PERCENTILE($C$2:$C$17, 0.75), "S", IF(C3>=PERCENTILE($C$2:$C$17, 0.5), "A", IF(C3>=PERCENTILE($C$2:$C$17, 0.25), "B", "C"))) -> A | G3: A | H3: =COUNTIF($E$2:$E$17, "A") -> 6
A4: MICA | B4: Analyst | C4: =AVERAGE(Table134[[#This Row],[ACADEMIC]],Table134[[#This Row],[SOCIAL]],Table134[[#This Row],[STRATEGIC]],Table134[[#This Row],[POWER]],Table134[[#This Row],[DEFENSE]]) -> 4.2 | D4: =RANK(C4,C2:C17,0) -> 4 | E4: =IF(C4>=PERCENTILE($C$2:$C$17, 0.75), "S", IF(C4>=PERCENTILE($C$2:$C$17, 0.5), "A", IF(C4>=PERCENTILE($C$2:$C$17, 0.25), "B", "C"))) -> S | G4: B | H4: =COUNTIF($E$2:$E$17, "B") -> 2
A5: GILLIAN | B5: Analyst | C5: =AVERAGE(Table134[[#This Row],[ACADEMIC]],Table134[[#This Row],[SOCIAL]],Table134[[#This Row],[STRATEGIC]],Table134[[#This Row],[POWER]],Table134[[#This Row],[DEFENSE]]) -> 4.4 | D5: =RANK(C5,C2:C17,0) -> 2 | E5: =IF(C5>=PERCENTILE($C$2:$C$17, 0.75), "S", IF(C5>=PERCENTILE($C$2:$C$17, 0.5), "A", IF(C5>=PERCENTILE($C$2:$C$17, 0.25), "B", "C"))) -> S | G5: C | H5: =COUNTIF($E$2:$E$17, "C") -> 4
A6: HAYAMI | B6: Explorer | C6: =AVERAGE(Table134[[#This Row],[ACADEMIC]],Table134[[#This Row],[SOCIAL]],Table134[[#This Row],[STRATEGIC]],Table134[[#This Row],[POWER]],Table134[[#This Row],[DEFENSE]]) -> 4.4 | D6: =RANK(C6,C2:C17,0) -> 2 | E6: =IF(C6>=PERCENTILE($C$2:$C$17, 0.75), "S", IF(C6>=PERCENTILE($C$2:$C$17, 0.5), "A", IF(C6>=PERCENTILE($C$2:$C$17, 0.25), "B", "C"))) -> S
A7: SHIINA | B7: Explorer | C7: =AVERAGE(Table134[[#This Row],[ACADEMIC]],Table134[[#This Row],[SOCIAL]],Table134[[#This Row],[STRATEGIC]],Table134[[#This Row],[POWER]],Table134[[#This Row],[DEFENSE]]) -> 3.4 | D7: =RANK(C7,C2:C17,0) -> 11 | E7: =IF(C7>=PERCENTILE($C$2:$C$17, 0.75), "S", IF(C7>=PERCENTILE($C$2:$C$17, 0.5), "A", IF(C7>=PERCENTILE($C$2:$C$17, 0.25), "B", "C"))) -> B | G7: Group | H7: Total Power
A8: SHAYE | B8: Explorer | C8: =AVERAGE(Table134[[#This Row],[ACADEMIC]],Table134[[#This Row],[SOCIAL]],Table134[[#This Row],[STRATEGIC]],Table134[[#This Row],[POWER]],Table134[[#This Row],[DEFENSE]]) -> 4 | D8: =RANK(C8,C2:C17,0) -> 5 | E8: =IF(C8>=PERCENTILE($C$2:$C$17, 0.75), "S", IF(C8>=PERCENTILE($C$2:$C$17, 0.5), "A", IF(C8>=PERCENTILE($C$2:$C$17, 0.25), "B", "C"))) -> A | G8: Analyst | H8: =SUMIF($B$2:$B$17, "analyst", $C$2:$C$17) -> 16.4
A9: THERESA | B9: Explorer | C9: =AVERAGE(Table134[[#This Row],[ACADEMIC]],Table134[[#This Row],[SOCIAL]],Table134[[#This Row],[STRATEGIC]],Table134[[#This Row],[POWER]],Table134[[#This Row],[DEFENSE]]) -> 3.2 | D9: =RANK(C9,C2:C17,0) -> 12 | E9: =IF(C9>=PERCENTILE($C$2:$C$17, 0.75), "S", IF(C9>=PERCENTILE($C$2:$C$17, 0.5), "A", IF(C9>=PERCENTILE($C$2:$C$17, 0.25), "B", "C"))) -> B | G9: Explorer | H9: =SUMIF($B$2:$B$17, "explorer", $C$2:$C$17) -> 15
A10: CHIYO | B10: Sentinel | C10: =AVERAGE(Table134[[#This Row],[ACADEMIC]],Table134[[#This Row],[SOCIAL]],Table134[[#This Row],[STRATEGIC]],Table134[[#This Row],[POWER]],Table134[[#This Row],[DEFENSE]]) -> 4 | D10: =RANK(C10,C2:C17,0) -> 5 | E10: =IF(C10>=PERCENTILE($C$2:$C$17, 0.75), "S", IF(C10>=PERCENTILE($C$2:$C$17, 0.5), "A", IF(C10>=PERCENTILE($C$2:$C$17, 0.25), "B", "C"))) -> A | G10: Sentinel | H10: =SUMIF($B$2:$B$17, "sentinel", $C$2:$C$17) -> 15.4
A11: MAYUMI | B11: Sentinel | C11: =AVERAGE(Table134[[#This Row],[ACADEMIC]],Table134[[#This Row],[SOCIAL]],Table134[[#This Row],[STRATEGIC]],Table134[[#This Row],[POWER]],Table134[[#This Row],[DEFENSE]]) -> 3.8 | D11: =RANK(C11,C2:C17,0) -> 8 | E11: =IF(C11>=PERCENTILE($C$2:$C$17, 0.75), "S", IF(C11>=PERCENTILE($C$2:$C$17, 0.5), "A", IF(C11>=PERCENTILE($C$2:$C$17, 0.25), "B", "C"))) -> A | G11: Diplomat | H11: =SUMIF($B$2:$B$17, "diplomat", $C$2:$C$17) -> 12.8
A12: SHIZUKA | B12: Sentinel | C12: =AVERAGE(Table134[[#This Row],[ACADEMIC]],Table134[[#This Row],[SOCIAL]],Table134[[#This Row],[STRATEGIC]],Table134[[#This Row],[POWER]],Table134[[#This Row],[DEFENSE]]) -> 4.6 | D12: =RANK(C12,C2:C17,0) -> 1 | E12: =IF(C12>=PERCENTILE($C$2:$C$17, 0.75), "S", IF(C12>=PERCENTILE($C$2:$C$17, 0.5), "A", IF(C12>=PERCENTILE($C$2:$C$17, 0.25), "B", "C"))) -> S
A13: LILY | B13: Sentinel | C13: =AVERAGE(Table134[[#This Row],[ACADEMIC]],Table134[[#This Row],[SOCIAL]],Table134[[#This Row],[STRATEGIC]],Table134[[#This Row],[POWER]],Table134[[#This Row],[DEFENSE]]) -> 3 | D13: =RANK(C13,C2:C17,0) -> 13 | E13: =IF(C13>=PERCENTILE($C$2:$C$17, 0.75), "S", IF(C13>=PERCENTILE($C$2:$C$17, 0.5), "A", IF(C13>=PERCENTILE($C$2:$C$17, 0.25), "B", "C"))) -> C
A14: KATIE | B14: Diplomat | C14: =AVERAGE(Table134[[#This Row],[ACADEMIC]],Table134[[#This Row],[SOCIAL]],Table134[[#This Row],[STRATEGIC]],Table134[[#This Row],[POWER]],Table134[[#This Row],[DEFENSE]]) -> 3 | D14: =RANK(C14,C2:C17,0) -> 13 | E14: =IF(C14>=PERCENTILE($C$2:$C$17, 0.75), "S", IF(C14>=PERCENTILE($C$2:$C$17, 0.5), "A", IF(C14>=PERCENTILE($C$2:$C$17, 0.25), "B", "C"))) -> C
A15: SONIA | B15: Diplomat | C15: =AVERAGE(Table134[[#This Row],[ACADEMIC]],Table134[[#This Row],[SOCIAL]],Table134[[#This Row],[STRATEGIC]],Table134[[#This Row],[POWER]],Table134[[#This Row],[DEFENSE]]) -> 3 | D15: =RANK(C15,C2:C17,0) -> 13 | E15: =IF(C15>=PERCENTILE($C$2:$C$17, 0.75), "S", IF(C15>=PERCENTILE($C$2:$C$17, 0.5), "A", IF(C15>=PERCENTILE($C$2:$C$17, 0.25), "B", "C"))) -> C
A16: EMILY | B16: Diplomat | C16: =AVERAGE(Table134[[#This Row],[ACADEMIC]],Table134[[#This Row],[SOCIAL]],Table134[[#This Row],[STRATEGIC]],Table134[[#This Row],[POWER]],Table134[[#This Row],[DEFENSE]]) -> 3 | D16: =RANK(C16,C2:C17,0) -> 13 | E16: =IF(C16>=PERCENTILE($C$2:$C$17, 0.75), "S", IF(C16>=PERCENTILE($C$2:$C$17, 0.5), "A", IF(C16>=PERCENTILE($C$2:$C$17, 0.25), "B", "C"))) -> C
A17: HIMIKO | B17: Diplomat | C17: =AVERAGE(Table134[[#This Row],[ACADEMIC]],Table134[[#This Row],[SOCIAL]],Table134[[#This Row],[STRATEGIC]],Table134[[#This Row],[POWER]],Table134[[#This Row],[DEFENSE]]) -> 3.8 | D17: =RANK(C17,C2:C17,0) -> 8 | E17: =IF(C17>=PERCENTILE($C$2:$C$17, 0.75), "S", IF(C17>=PERCENTILE($C$2:$C$17, 0.5), "A", IF(C17>=PERCENTILE($C$2:$C$17, 0.25), "B", "C"))) -> A
A42: Name | B42: Group | C42: Avg Stat | D42: Rank | E42: Tier
A43: {=_xlfn._xlws.SORT(Table7[],3,-1)} -> SHIZUKA | B43: Sentinel | C43: 4.6 | D43: 1 | E43: S
A44: GILLIAN | B44: Analyst | C44: 4.4 | D44: 2 | E44: S
A45: HAYAMI | B45: Explorer | C45: 4.4 | D45: 2 | E45: S
A46: MICA | B46: Analyst | C46: 4.2 | D46: 4 | E46: S
A47: HIROMI | B47: Analyst | C47: 4 | D47: 5 | E47: A
A48: SHAYE | B48: Explorer | C48: 4 | D48: 5 | E48: A
A49: CHIYO | B49: Sentinel | C49: 4 | D49: 5 | E49: A
A50: PAULA | B50: Analyst | C50: 3.8 | D50: 8 | E50: A
A51: MAYUMI | B51: Sentinel | C51: 3.8 | D51: 8 | E51: A
A52: HIMIKO | B52: Diplomat | C52: 3.8 | D52: 8 | E52: A
A53: SHIINA | B53: Explorer | C53: 3.4 | D53: 11 | E53: B
A54: THERESA | B54: Explorer | C54: 3.2 | D54: 12 | E54: B
A55: LILY | B55: Sentinel | C55: 3 | D55: 13 | E55: C
... A58: EMILY | B58: Diplomat | C58: 3 | D58: 13 | E58: C

Sheet Radar
A1: STAT | B1: PAULA | C1: HIROMI | D1: MICA | E1: GILLIAN | F1: HAYAMI | G1: SHIINA | H1: SHAYE | I1: THERESA | J1: CHIYO | K1: MAYUMI | L1: SHIZUKA | M1: LILY | N1: KATIE | O1: SONIA | P1: EMILY | Q1: HIMIKO
A2: Power | B2: 75 | C2: 80 | D2: 70 | E2: 90 | F2: 95 | G2: 70 | H2: 88 | I2: 60 | J2: 78 | K2: 75 | L2: 92 | M2: 55 | N2: 72 | O2: 60 | P2: 55 | Q2: 65
A3: Visionary | B3: 90 | C3: 95 | D3: 85 | E3: 80 | F3: 70 | G3: 65 | H3: 50 | I3: 45 | J3: 85 | K3: 60 | L3: 65 | M3: 50 | N3: 80 | O3: 88 | P3: 85 | Q3: 78
A4: Resourcefulness | B4: 80 | C4: 75 | D4: 88 | E4: 85 | F4: 98 | G4: 78 | H4: 85 | I4: 80 | J4: 70 | K4: 72 | L4: 80 | M4: 70 | N4: 60 | O4: 72 | P4: 78 | Q4: 70
A5: Communication | B5: 45 | C5: 40 | D5: 80 | E5: 75 | F5: 55 | G5: 50 | H5: 65 | I5: 75 | J5: 45 | K5: 50 | L5: 70 | M5: 88 | N5: 55 | O5: 50 | P5: 78 | Q5: 88
A6: Extraversion | B6: 20 | C6: 20 | D6: 85 | E6: 80 | F6: 35 | G6: 25 | H6: 85 | I6: 88 | J6: 25 | K6: 20 | L6: 80 | M6: 88 | N6: 25 | O6: 20 | P6: 85 | Q6: 88
A7: Socialibility | B7: 25 | C7: 20 | D7: 75 | E7: 60 | F7: 35 | G7: 50 | H7: 70 | I7: 90 | J7: 40 | K7: 55 | L7: 65 | M7: 95 | N7: 45 | O7: 40 | P7: 80 | Q7: 90
A8: Empathy | B8: 35 | C8: 25 | D8: 40 | E8: 30 | F8: 45 | G8: 80 | H8: 30 | I8: 75 | J8: 50 | K8: 90 | L8: 25 | M8: 88 | N8: 95 | O8: 88 | P8: 80 | Q8: 85
A9: Self-Control | B9: 60 | C9: 70 | D9: 35 | E9: 55 | F9: 65 | G9: 65 | H9: 30 | I9: 40 | J9: 88 | K9: 80 | L9: 50 | M9: 45 | N9: 40 | O9: 70 | P9: 25 | Q9: 55
A10: Conscientiousness | B10: 65 | C10: 80 | D10: 45 | E10: 75 | F10: 60 | G10: 70 | H10: 35 | I10: 45 | J10: 90 | K10: 85 | L10: 70 | M10: 65 | N10: 55 | O10: 65 | P10: 30 | Q10: 65
A11: Rationality | B11: 95 | C11: 98 | D11: 85 | E11: 88 | F11: 80 | G11: 60 | H11: 60 | I11: 45 | J11: 75 | K11: 65 | L11: 78 | M11: 50 | N11: 55 | O11: 85 | P11: 55 | Q11: 60
A12: Assurance | B12: 55 | C12: 65 | D12: 88 | E12: 95 | F12: 75 | G12: 45 | H12: 88 | I12: 70 | J12: 60 | K12: 40 | L12: 95 | M12: 70 | N12: 35 | O12: 55 | P12: 65 | Q12: 80
